Workbook

Sheet CVM
A1: Data_Posicao | B1: ID_CNPJ_Fundo | C1: Nome_Fundo | D1: Fonte | E1: Tem na Raspagem
A2: 46171 | B2: 05754060000113 | C2: CATERPILLAR FUNDO DE INVESTIMENTO EM DIREITOS CREDITÓRIOS DO SEGMENTO INDUSTRIAL II - RESP LIMITADA | D2: CVM | E2: =_xlfn.XLOOKUP(B2,RASPAGEM_REGULAMENTOS!A:A,RASPAGEM_REGULAMENTOS!C:C) -> Raspagem
A3: 46171 | B3: 06018364000185 | C3: FUNDO DE INVESTIMENTO EM DIREITOS CREDITÓRIOS - FIDC PREMIUM | D3: CVM | E3: =_xlfn.XLOOKUP(B3,RASPAGEM_REGULAMENTOS!A:A,RASPAGEM_REGULAMENTOS!C:C) -> Raspagem
A4: 46171 | B4: 06081379000198 | C4: KOL FUNDO DE INVESTIMENTO EM DIREITOS CREDITÓRIOS NÃO-PADRONIZADOS | D4: CVM | E4: =_xlfn.XLOOKUP(B4,RASPAGEM_REGULAMENTOS!A:A,RASPAGEM_REGULAMENTOS!C:C) -> Raspagem
A5: 46171 | B5: 06182371000118 | C5: FOR-TE FIDC | D5: CVM | E5: =_xlfn.XLOOKUP(B5,RASPAGEM_REGULAMENTOS!A:A,RASPAGEM_REGULAMENTOS!C:C) -> Raspagem
A6: 46171 | B6: 07084253000130 | C6: MULTI INFRA FUNDO DE INVESTIMENTO EM DIREITOS CREDITÓRIOS NÃO-PADRONIZADOS | D6: CVM | E6: =_xlfn.XLOOKUP(B6,RASPAGEM_REGULAMENTOS!A:A,RASPAGEM_REGULAMENTOS!C:C) -> Raspagem
A7: 46171 | B7: 07383363000100 | C7: RIVO FUNDO DE INVESTIMENTO EM DIREITOS CREDITÓRIOS | D7: CVM | E7: =_xlfn.XLOOKUP(B7,RASPAGEM_REGULAMENTOS!A:A,RASPAGEM_REGULAMENTOS!C:C) -> Raspagem
A8: 46171 | B8: 07507899000182 | C8: GP FIDC FCVS | D8: CVM | E8: =_xlfn.XLOOKUP(B8,RASPAGEM_REGULAMENTOS!A:A,RASPAGEM_REGULAMENTOS!C:C) -> Raspagem
A9: 46171 | B9: 07727002000126 | C9: FIDC PCG - BRASIL MULTICARTEIRA | D9: CVM | E9: =_xlfn.XLOOKUP(B9,RASPAGEM_REGULAMENTOS!A:A,RASPAGEM_REGULAMENTOS!C:C) -> Raspagem
A10: 46171 | B10: 07727757000120 | C10: EMPRESARIAL FUNDO DE INVESTIMENTO EM DIREITOS CREDITÓRIOS MULTISEGMENTOS | D10: CVM | E10: =_xlfn.XLOOKUP(B10,RASPAGEM_REGULAMENTOS!A:A,RASPAGEM_REGULAMENTOS!C:C) -> Raspagem
A11: 46171 | B11: 07738319000168 | C11: SP RECEBÍVEIS PREMIUM I FUNDO DE INVESTIMENTO EM DIREITOS CREDITÓRIOS MULTISSEGMENTOS | D11: CVM | E11: =_xlfn.XLOOKUP(B11,RASPAGEM_REGULAMENTOS!A:A,RASPAGEM_REGULAMENTOS!C:C) -> Raspagem
A12: 46171 | B12: 07742454000187 | C12: GP - FIDC FCVS 2 | D12: CVM | E12: =_xlfn.XLOOKUP(B12,RASPAGEM_REGULAMENTOS!A:A,RASPAGEM_REGULAMENTOS!C:C) -> Raspagem
A13: 46171 | B13: 08093745000154 | C13: V1 FUNDO DE INVESTIMENTO EM DIREITOS CREDITÓRIOS - MULTICARTEIRA | D13: CVM | E13: =_xlfn.XLOOKUP(B13,RASPAGEM_REGULAMENTOS!A:A,RASPAGEM_REGULAMENTOS!C:C) -> Raspagem
... A4222: 46171 | B4222: 97533979000103 | C4222: FUNDO DE INVESTIMENTO EM DIREITOS CREDITORIOS CASH FLOW MULTISSEGMENTOS | D4222: CVM | E4222: =_xlfn.XLOOKUP(B4222,RASPAGEM_REGULAMENTOS!A:A,RASPAGEM_REGULAMENTOS!C:C) -> Raspagem

Sheet RASPAGEM_REGULAMENTOS
A1: cnpj_tratado | B1: nome_fundo | C1: Fonte
A2: 09009924000123 | B2: Eco – Multi Commodities Fundo de Investimento em Direitos Creditórios Agropecuários | C2: Raspagem
A3: 17198822000121 | B3: ROVENSA FUNDO DE INVESTIMENTO EM DIREITOS CREDITÓRIOS AGRONEGÓCIO RESPONSABILIDADE LIMITADA | C3: Raspagem
A4: 18686800000173 | B4: CERRADO I FUNDO DE INVESTIMENTO EM DIREITOS CREDITÓRIOS | C4: Raspagem
A5: 20998706000100 | B5: FMC 202201 FUNDO DE INVESTIMENTO EM DIREITOS CREDITÓRIOS – RESPONSABILIDADE LIMITADA | C5: Raspagem
A6: 24270541000106 | B6: DISAM CASH - FUNDO DE INVESTIMENTO EM DIREITOS CREDITÓRIOS DO AGRONEGÓCIO DE RESPONSABILIDADE ILIMITADA | C6: Raspagem
A7: 25382606000160 | B7: URA AGRO FUNDO DE INVESTIMENTO EM DIREITOS CREDITÓRIOS – RESPONSABILIDADE LIMITADA | C7: Raspagem
A8: 25382606000160 | C8: Raspagem
A9: 26459204000189 | B9: JAPUÍRA FUNDO DE INVESTIMENTO EM DIREITOS CREDITÓRIOS - RESPONSABILIDADE LIMITADA | C9: Raspagem
A10: 28472392000100 | B10: UPL 1 FUNDO DE INVESTIMENTO EM DIREITOS CREDITÓRIOS AGRONEGÓCIO | C10: Raspagem
A11: 31771948000174 | B11: VLA FUNDO DE INVESTIMENTO EM DIREITOS CREDITÓRIOS – RESPONSABILIDADE LIMITADA | C11: Raspagem
A12: 35654776000100 | B12: PANTANAL DO BRASIL FUNDO DE INVESTIMENTO EM DIREITOS CREDITÓRIOS NÃO PADRONIZADOS | C12: Raspagem
A13: 37035910000110 | B13: AG LIFE FUNDO DE INVESTIMENTO EM DIREITOS CREDITÓRIOS | C13: Raspagem
A14: 37036039000179 | B14: GREEN LIFE ESG FUNDO DE INVESTIMENTO EM DIREITOS CREDITÓRIOS | C14: Raspagem
A15: 40365928000194 | B15: FARM II FUNDO DE INVESTIMENTO EM DIREITOS CREDITÓRIOS RESPONSABILIDADE LIMITADA | C15: Raspagem
A16: 40365928000194 | C16: Raspagem
A17: 41196339000192 | B17: SYNGENTA TECH I FUNDO DE INVESTIMENTO EM DIREITOS CREDITÓRIOS DE RESPONSABILIDADE ILIMITADA | C17: Raspagem
A18: 41196339000192 | C18: Raspagem
A19: 41196339000192 | B19: SYNGENTA TECH I FUNDO DE INVESTIMENTO EM DIREITOS CREDITÓRIOS | C19: Raspagem
A20: 42336323000109 | B20: CERES CONFINA FUNDO DE INVESTIMENTO EM DIREITOS CREDITÓRIOS – RESPONSABILIDADE LIMITADA | C20: Raspagem
A21: 43616659000180 | B21: TALÓ 1 FUNDO DE INVESTIMENTO EM DIREITOS CREDITÓRIOS RESPONSABILIDADE LIMITADA | C21: Raspagem
A22: 44302112000172 | B22: FUNDO DE INVESTIMENTO EM DIREITOS CREDITÓRIOS AGRO CITI-BAYER RESPONSABILIDADE LIMITADA | C22: Raspagem
A23: 44613189000163 | B23: BIOMA INVESTIMENTOS FIAGRO EM DIREITOS CREDITÓRIOS | C23: Raspagem
A24: 46073195000109 | B24: FUNDO DE INVESTIMENTO EM DIREITOS CREDITÓRIOS AGRO CITI-SYNGENTA | C24: Raspagem
A25: 46073195000109 | B25: FUNDO DE INVESTIMENTO EM DIREITOS CREDITÓRIOS AGRO CITI-SYNGENTA RESPONSABILIDADE LIMITADA | C25: Raspagem
A26: 46390186000133 | B26: SEED FUNDO DE INVESTIMENTO EM DIREITOS CREDITÓRIOS NÃO PADRONIZADOS | C26: Raspagem
A27: 46390255000109 | B27: CULTURA AGROMAIS FUNDO DE INVESTIMENTO EM DIREITOS CREDITÓRIOS | C27: Raspagem
A28: 46442274000131 | B28: FARM III FUNDO DE INVESTIMENTO EM DIREITOS CREDITÓRIOS RESPONSABILIDADE LIMITADA | C28: Raspagem
A29: 47228232000165 | B29: Classe Única Agro Flex Fundo de Investimento em Direitos Creditórios – Responsabilidade Limitada | C29: Raspagem
A30: 47228232000165 | C30: Raspagem
A31: 47669450000135 | B31: MAKALU FUNDO DE INVESTIMENTO EM DIREITOS CREDITÓRIOS RESPONSABILIDADE LIMITADA | C31: Raspagem
A32: 47936587000109 | B32: FARM M II FUNDO DE INVESTIMENTO EM DIREITOS CREDITÓRIOS RESPONSABILIDADE LIMITADA | C32: Raspagem
A33: 47936587000109 | C33: Raspagem
A34: 48313595000161 | B34: IBBA AGRO BR FUNDO DE INVESTIMENTO EM DIREITOS CREDITÓRIOS | C34: Raspagem
A35: 48660463000106 | B35: FARMTECH UP CREDIT FUNDO DE INVESTIMENTO EM DIREITOS CREDITÓRIOS | C35: Raspagem
A36: 48660463000106 | B36: Fundo de Investimento em Direitos Creditórios | C36: Raspagem
A37: 48890745000108 | B37: G5 FARM FUNDO DE INVESTIMENTO EM COTAS DE FUNDOS DE INVESTIMENTO EM DIREITOS CREDITÓRIOS III | C37: Raspagem
A38: 48935526000190 | B38: CERES CRA FUNDO DE INVESTIMENTO EM DIREITOS CREDITÓRIOS | C38: Raspagem
A39: 50519168000186 | B39: STRUTTURA AGRO FUNDO DE INVESTIMENTO EM DIREITOS CREDITÓRIOS DO AGRONEGÓCIO | C39: Raspagem
A40: 51554551000138 | B40: CRÉDITO NITRO AGRO – RESPONSABILIDADE LIMITADA | C40: Raspagem
...
